Workbook
Name AvgDate: Ranking_Pivot!$Q$5
Name AvgPrice: Ranking_Pivot!$P$5
Name AvgRAM: Ranking_Pivot!$M$5
Name AvgROM: Ranking_Pivot!$N$5
Name AvgSize: Ranking_Pivot!$O$5
Name MaxDate: Ranking_Pivot!$Q$7
Name MaxPrice: Ranking_Pivot!$P$7
Name MaxRAM: Ranking_Pivot!$M$7
Name MaxReleased: Ranking_Pivot!#REF!
Name MaxROM: Ranking_Pivot!$N$7
Name MaxSize: Ranking_Pivot!$O$7
Name MinDate: Ranking_Pivot!$Q$6
Name MinPrice: Ranking_Pivot!$P$6
Name MinRAM: Ranking_Pivot!$M$6
Name MinROM: Ranking_Pivot!$N$6
Name MinSize: Ranking_Pivot!$O$6
Name Price: Ranking_Pivot!#REF!
Name priceieie: Ranking_Pivot!#REF!
Name RangeRAM: Ranking_Pivot!$M$8
Name RangeROM: Ranking_Pivot!$N$8
Name Slicer_brand: #N/A
Name Slicer_performance_tier: #N/A
Name Slicer_released__Year: #N/A
Name Slicer_rom_type: #N/A
Name Slicer_size_tier: #N/A
Name Slicer_system_name: #N/A
Name Slicer_use_case: #N/A
Name userProfile: #REF!

Sheet screen_size_preferences
A1: use_case | B1: min_size | C1: max_size | D1: peak_size | E1: max_score | F1: penalty_per_inch
A2: student | B2: 13 | C2: 16 | D2: 14.5 | E2: 100 | F2: 8
A3: office | B3: 13 | C3: 17 | D3: 15.6 | E3: 100 | F3: 6
A4: gamer | B4: 15 | C4: 18 | D4: 16.5 | E4: 100 | F4: 5
A5: designer | B5: 16 | C5: 18 | D5: 17 | E5: 100 | F5: 4

Sheet Ranking_Pivot
A3: Laptop | B3: Variants | C3: Maximum RAM | D3: Maximum ROM | E3: Max Screen Size | F3: Max Resolution | G3: Lowest Price | H3: Latest Released | I3: Score
A4: Apple MacBook Pro M4 | B4: 13 | C4: 48 | D4: 1024 | E4: 16.2 | F4: 3456 x 2234 | G4: 105641 | H4: 45597 | I4: 82.29 | M4: GB | N4: GB | O4: "
A5: Asus ROG Flow Z13 | B5: 6 | C5: 32 | D5: 1024 | E5: 13.4 | F5: 3840 x 2400 | G5: 64808 | H5: 45778 | I5: 76.99 | M5: =IFERROR(ROUND(AVERAGEIF(C4:C18,"<>"),0)&M4,"No Data") -> 37 GB | N5: =IFERROR(ROUND(AVERAGEIF(D4:D18,"<>"),0)&N4,"No Data") -> 1434 GB | O5: =IFERROR(ROUND(AVERAGEIF(E4:E18,"<>"),0)&O4,"No Data") -> 15" | P5: =IFERROR(ROUND(AVERAGEIF(G4:G18,"<>"),0),"No Data") -> 106862 | Q5: =IFERROR(ROUND(AVERAGEIF(H4:H18,"<>"),0),"No Data") -> 45436
A6: MSI Stealth 17 Studio | B6: 1 | C6: 64 | D6: 2048 | E6: 17.3 | F6: 3840 x 2160 | G6: 185181 | H6: 44958 | I6: 76.78 | M6: =IF(COUNTA(C4:C18)<>0,MIN(C4:C18)&M4,"No Data") -> 24 GB | N6: =IF(COUNTA(D4:D18)<>0,MIN(D4:D18)&N4,"No Data") -> 512 GB | O6: =IF(COUNTA(E4:E18)<>0,MIN(E4:E18)&O4,"No Data") -> 13.4" | P6: =IF(COUNTA(G4:G18)<>0,MIN(G4:G18),"No Data") -> 42065 | Q6: =IF(COUNTA(H4:H18)<>0,MIN(H4:H18),"No Data") -> 44743
A7: Asus ROG Zephyrus G14 | B7: 10 | C7: 32 | D7: 2048 | E7: 14 | F7: 2880 x 1800 | G7: 79067 | H7: 45778 | I7: 75.79 | M7: =IF(COUNTA(C4:C18)<>0,MAX(C4:C18)&M4,"No Data") -> 64 GB | N7: =IF(COUNTA(D4:D18)<>0,MAX(D4:D18)&N4,"No Data") -> 2048 GB | O7: =IF(COUNTA(E4:E18)<>0,MAX(E4:E18)&O4,"No Data") -> 17.3" | P7: =IF(COUNTA(G4:G18)<>0,MAX(G4:G18),"No Data") -> 250830 | Q7: =IF(COUNTA(H4:H18)<>0,MAX(H4:H18),"No Data") -> 45778
A8: Apple MacBook Air M4 | B8: 22 | C8: 24 | D8: 512 | E8: 15.3 | F8: 2880 x 1864 | G8: 61567 | H8: 45717 | I8: 75.07 | M8: =IF(MinRAM ="No Data","No Data",MinRAM&" - "&MaxRAM) -> 24 GB - 64 GB | N8: =IF(MinROM ="No Data","No Data",MinROM&" - "&MaxROM) -> 512 GB - 2048 GB
A9: Asus ROG Flow X13 | B9: 6 | C9: 32 | D9: 1024 | E9: 13.4 | F9: 3840 x 2400 | G9: 58327 | H9: 45047 | I9: 75.05
A10: MSI Titan GT77 HX | B10: 1 | C10: 64 | D10: 2048 | E10: 17.3 | F10: 3840 x 2160 | G10: 250830 | H10: 44958 | I10: 74.1
A11: Apple MacBook Pro M3 Pro | B11: 6 | C11: 36 | D11: 1024 | E11: 16.2 | F11: 3456 x 2234 | G11: 123082 | H11: 45231 | I11: 74.06
A12: Asus Zenbook 14 OLED | B12: 11 | C12: 32 | D12: 1024 | E12: 14 | F12: 2880 x 1800 | G12: 42065 | H12: 45689 | I12: 73.8
A13: MSI Stealth 16 Mercedes AMG | B13: 2 | C13: 32 | D13: 2048 | E13: 16 | F13: 3840 x 2400 | G13: 162029 | H13: 45108 | I13: 72.85
A14: Asus TUF Gaming A14 | B14: 3 | C14: 32 | D14: 2048 | E14: 14 | F14: 2560 x 1600 | G14: 84252 | H14: 45717 | I14: 72.77
A15: Apple MacBook Air M3 | B15: 28 | C15: 24 | D15: 512 | E15: 15.3 | F15: 2880 x 1864 | G15: 61963 | H15: 45658 | I15: 72.53
A16: Asus ROG Zephyrus Duo 16 | B16: 3 | C16: 32 | D16: 2048 | E16: 16 | F16: 3840 x 2400 | G16: 104472 | H16: 44743 | I16: 72.26
A17: Asus ROG Strix Scar 16 | B17: 5 | C17: 32 | D17: 2048 | E17: 16 | F17: 2560 x 1600 | G17: 149066 | H17: 45778 | I17: 72.17
A18: Asus ROG Strix G16 | B18: 7 | C18: 32 | D18: 1024 | E18: 16 | F18: 2560 x 1600 | G18: 70583 | H18: 45778 | I18: 71.89

Sheet Ranking
B21: Laptop | C21: Variants | D21: Maximum RAM | E21: Maximum ROM | F21: Max Screen Size | G21: Max Resolution | H21: Lowest Price | I21: Latest Released | J21: Remarks
B22: =IF(ISBLANK(Ranking_Pivot!A4),"",Ranking_Pivot!A4) -> Apple MacBook Pro M4 | C22: =IF(ISBLANK(Ranking_Pivot!B4),"",Ranking_Pivot!B4) -> 13 | D22: =IF(ISBLANK(Ranking_Pivot!C4),"",(Ranking_Pivot!C4)&" GB") -> 48 GB | E22: =IF(ISBLANK(Ranking_Pivot!D4),"",(Ranking_Pivot!D4)&" GB") -> 1024 GB | F22: =IF(ISBLANK(Ranking_Pivot!E4),"",Ranking_Pivot!E4&" """) -> 16.2 " | G22: =IF(ISBLANK(Ranking_Pivot!F4),"",Ranking_Pivot!F4) -> 3456 x 2234 | H22: =IF(ISBLANK(Ranking_Pivot!G4),"",Ranking_Pivot!G4) -> 105641 | I22: =IF(ISBLANK(Ranking_Pivot!H4),"",Ranking_Pivot!H4) -> 45597 | J22: =IF(ISBLANK(Ranking_Table[[#This Row],[Lowest Price]]),"",IF(Ranking_Table[[#This Row],[Lowest Price]]=MIN(Ranking_Table[Lowest Price]), "Most Affordable", IF(Ranking_Table[[#This Row],[Lowest Price]]=MAX(Ranking_Table[Lowest Price]), "Most Expensive", "")))
B23: =IF(ISBLANK(Ranking_Pivot!A5),"",Ranking_Pivot!A5) -> Asus ROG Flow Z13 | C23: =IF(ISBLANK(Ranking_Pivot!B5),"",Ranking_Pivot!B5) -> 6 | D23: =IF(ISBLANK(Ranking_Pivot!C5),"",(Ranking_Pivot!C5)&" GB") -> 32 GB | E23: =IF(ISBLANK(Ranking_Pivot!D5),"",(Ranking_Pivot!D5)&" GB") -> 1024 GB | F23: =IF(ISBLANK(Ranking_Pivot!E5),"",Ranking_Pivot!E5&" """) -> 13.4 " | G23: =IF(ISBLANK(Ranking_Pivot!F5),"",Ranking_Pivot!F5) -> 3840 x 2400 | H23: =IF(ISBLANK(Ranking_Pivot!G5),"",Ranking_Pivot!G5) -> 64808 | I23: =IF(ISBLANK(Ranking_Pivot!H5),"",Ranking_Pivot!H5) -> 45778 | J23: =IF(ISBLANK(Ranking_Table[[#This Row],[Lowest Price]]),"",IF(Ranking_Table[[#This Row],[Lowest Price]]=MIN(Ranking_Table[Lowest Price]), "Most Affordable", IF(Ranking_Table[[#This Row],[Lowest Price]]=MAX(Ranking_Table[Lowest Price]), "Most Expensive", "")))
B24: =IF(ISBLANK(Ranking_Pivot!A6),"",Ranking_Pivot!A6) -> MSI Stealth 17 Studio | C24: =IF(ISBLANK(Ranking_Pivot!B6),"",Ranking_Pivot!B6) -> 1 | D24: =IF(ISBLANK(Ranking_Pivot!C6),"",(Ranking_Pivot!C6)&" GB") -> 64 GB | E24: =IF(ISBLANK(Ranking_Pivot!D6),"",(Ranking_Pivot!D6)&" GB") -> 2048 GB | F24: =IF(ISBLANK(Ranking_Pivot!E6),"",Ranking_Pivot!E6&" """) -> 17.3 " | G24: =IF(ISBLANK(Ranking_Pivot!F6),"",Ranking_Pivot!F6) -> 3840 x 2160 | H24: =IF(ISBLANK(Ranking_Pivot!G6),"",Ranking_Pivot!G6) -> 185181 | I24: =IF(ISBLANK(Ranking_Pivot!H6),"",Ranking_Pivot!H6) -> 44958 | J24: =IF(ISBLANK(Ranking_Table[[#This Row],[Lowest Price]]),"",IF(Ranking_Table[[#This Row],[Lowest Price]]=MIN(Ranking_Table[Lowest Price]), "Most Affordable", IF(Ranking_Table[[#This Row],[Lowest Price]]=MAX(Ranking_Table[Lowest Price]), "Most Expensive", "")))
B25: =IF(ISBLANK(Ranking_Pivot!A7),"",Ranking_Pivot!A7) -> Asus ROG Zephyrus G14 | C25: =IF(ISBLANK(Ranking_Pivot!B7),"",Ranking_Pivot!B7) -> 10 | D25: =IF(ISBLANK(Ranking_Pivot!C7),"",(Ranking_Pivot!C7)&" GB") -> 32 GB | E25: =IF(ISBLANK(Ranking_Pivot!D7),"",(Ranking_Pivot!D7)&" GB") -> 2048 GB | F25: =IF(ISBLANK(Ranking_Pivot!E7),"",Ranking_Pivot!E7&" """) -> 14 " | G25: =IF(ISBLANK(Ranking_Pivot!F7),"",Ranking_Pivot!F7) -> 2880 x 1800 | H25: =IF(ISBLANK(Ranking_Pivot!G7),"",Ranking_Pivot!G7) -> 79067 | I25: =IF(ISBLANK(Ranking_Pivot!H7),"",Ranking_Pivot!H7) -> 45778 | J25: =IF(ISBLANK(Ranking_Table[[#This Row],[Lowest Price]]),"",IF(Ranking_Table[[#This Row],[Lowest Price]]=MIN(Ranking_Table[Lowest Price]), "Most Affordable", IF(Ranking_Table[[#This Row],[Lowest Price]]=MAX(Ranking_Table[Lowest Price]), "Most Expensive", "")))
B26: =IF(ISBLANK(Ranking_Pivot!A8),"",Ranking_Pivot!A8) -> Apple MacBook Air M4 | C26: =IF(ISBLANK(Ranking_Pivot!B8),"",Ranking_Pivot!B8) -> 22 | D26: =IF(ISBLANK(Ranking_Pivot!C8),"",(Ranking_Pivot!C8)&" GB") -> 24 GB | E26: =IF(ISBLANK(Ranking_Pivot!D8),"",(Ranking_Pivot!D8)&" GB") -> 512 GB | F26: =IF(ISBLANK(Ranking_Pivot!E8),"",Ranking_Pivot!E8&" """) -> 15.3 " | G26: =IF(ISBLANK(Ranking_Pivot!F8),"",Ranking_Pivot!F8) -> 2880 x 1864 | H26: =IF(ISBLANK(Ranking_Pivot!G8),"",Ranking_Pivot!G8) -> 61567 | I26: =IF(ISBLANK(Ranking_Pivot!H8),"",Ranking_Pivot!H8) -> 45717 | J26: =IF(ISBLANK(Ranking_Table[[#This Row],[Lowest Price]]),"",IF(Ranking_Table[[#This Row],[Lowest Price]]=MIN(Ranking_Table[Lowest Price]), "Most Affordable", IF(Ranking_Table[[#This Row],[Lowest Price]]=MAX(Ranking_Table[Lowest Price]), "Most Expensive", "")))
B27: =IF(ISBLANK(Ranking_Pivot!A9),"",Ranking_Pivot!A9) -> Asus ROG Flow X13 | C27: =IF(ISBLANK(Ranking_Pivot!B9),"",Ranking_Pivot!B9) -> 6 | D27: =IF(ISBLANK(Ranking_Pivot!C9),"",(Ranking_Pivot!C9)&" GB") -> 32 GB | E27: =IF(ISBLANK(Ranking_Pivot!D9),"",(Ranking_Pivot!D9)&" GB") -> 1024 GB | F27: =IF(ISBLANK(Ranking_Pivot!E9),"",Ranking_Pivot!E9&" """) -> 13.4 " | G27: =IF(ISBLANK(Ranking_Pivot!F9),"",Ranking_Pivot!F9) -> 3840 x 2400 | H27: =IF(ISBLANK(Ranking_Pivot!G9),"",Ranking_Pivot!G9) -> 58327 | I27: =IF(ISBLANK(Ranking_Pivot!H9),"",Ranking_Pivot!H9) -> 45047 | J27: =IF(ISBLANK(Ranking_Table[[#This Row],[Lowest Price]]),"",IF(Ranking_Table[[#This Row],[Lowest Price]]=MIN(Ranking_Table[Lowest Price]), "Most Affordable", IF(Ranking_Table[[#This Row],[Lowest Price]]=MAX(Ranking_Table[Lowest Price]), "Most Expensive", "")))
B28: =IF(ISBLANK(Ranking_Pivot!A10),"",Ranking_Pivot!A10) -> MSI Titan GT77 HX | C28: =IF(ISBLANK(Ranking_Pivot!B10),"",Ranking_Pivot!B10) -> 1 | D28: =IF(ISBLANK(Ranking_Pivot!C10),"",(Ranking_Pivot!C10)&" GB") -> 64 GB | E28: =IF(ISBLANK(Ranking_Pivot!D10),"",(Ranking_Pivot!D10)&" GB") -> 2048 GB | F28: =IF(ISBLANK(Ranking_Pivot!E10),"",Ranking_Pivot!E10&" """) -> 17.3 " | G28: =IF(ISBLANK(Ranking_Pivot!F10),"",Ranking_Pivot!F10) -> 3840 x 2160 | H28: =IF(ISBLANK(Ranking_Pivot!G10),"",Ranking_Pivot!G10) -> 250830 | I28: =IF(ISBLANK(Ranking_Pivot!H10),"",Ranking_Pivot!H10) -> 44958 | J28: =IF(ISBLANK(Ranking_Table[[#This Row],[Lowest Price]]),"",IF(Ranking_Table[[#This Row],[Lowest Price]]=MIN(Ranking_Table[Lowest Price]), "Most Affordable", IF(Ranking_Table[[#This Row],[Lowest Price]]=MAX(Ranking_Table[Lowest Price]), "Most Expensive", ""))) -> Most Expensive
B29: =IF(ISBLANK(Ranking_Pivot!A11),"",Ranking_Pivot!A11) -> Apple MacBook Pro M3 Pro | C29: =IF(ISBLANK(Ranking_Pivot!B11),"",Ranking_Pivot!B11) -> 6 | D29: =IF(ISBLANK(Ranking_Pivot!C11),"",(Ranking_Pivot!C11)&" GB") -> 36 GB | E29: =IF(ISBLANK(Ranking_Pivot!D11),"",(Ranking_Pivot!D11)&" GB") -> 1024 GB | F29: =IF(ISBLANK(Ranking_Pivot!E11),"",Ranking_Pivot!E11&" """) -> 16.2 " | G29: =IF(ISBLANK(Ranking_Pivot!F11),"",Ranking_Pivot!F11) -> 3456 x 2234 | H29: =IF(ISBLANK(Ranking_Pivot!G11),"",Ranking_Pivot!G11) -> 123082 | I29: =IF(ISBLANK(Ranking_Pivot!H11),"",Ranking_Pivot!H11) -> 45231 | J29: =IF(ISBLANK(Ranking_Table[[#This Row],[Lowest Price]]),"",IF(Ranking_Table[[#This Row],[Lowest Price]]=MIN(Ranking_Table[Lowest Price]), "Most Affordable", IF(Ranking_Table[[#This Row],[Lowest Price]]=MAX(Ranking_Table[Lowest Price]), "Most Expensive", "")))
B30: =IF(ISBLANK(Ranking_Pivot!A12),"",Ranking_Pivot!A12) -> Asus Zenbook 14 OLED | C30: =IF(ISBLANK(Ranking_Pivot!B12),"",Ranking_Pivot!B12) -> 11 | D30: =IF(ISBLANK(Ranking_Pivot!C12),"",(Ranking_Pivot!C12)&" GB") -> 32 GB | E30: =IF(ISBLANK(Ranking_Pivot!D12),"",(Ranking_Pivot!D12)&" GB") -> 1024 GB | F30: =IF(ISBLANK(Ranking_Pivot!E12),"",Ranking_Pivot!E12&" """) -> 14 " | G30: =IF(ISBLANK(Ranking_Pivot!F12),"",Ranking_Pivot!F12) -> 2880 x 1800 | H30: =IF(ISBLANK(Ranking_Pivot!G12),"",Ranking_Pivot!G12) -> 42065 | I30: =IF(ISBLANK(Ranking_Pivot!H12),"",Ranking_Pivot!H12) -> 45689 | J30: =IF(ISBLANK(Ranking_Table[[#This Row],[Lowest Price]]),"",IF(Ranking_Table[[#This Row],[Lowest Price]]=MIN(Ranking_Table[Lowest Price]), "Most Affordable", IF(Ranking_Table[[#This Row],[Lowest Price]]=MAX(Ranking_Table[Lowest Price]), "Most Expensive", ""))) -> Most Affordable
B31: =IF(ISBLANK(Ranking_Pivot!A13),"",Ranking_Pivot!A13) -> MSI Stealth 16 Mercedes AMG | C31: =IF(ISBLANK(Ranking_Pivot!B13),"",Ranking_Pivot!B13) -> 2 | D31: =IF(ISBLANK(Ranking_Pivot!C13),"",(Ranking_Pivot!C13)&" GB") -> 32 GB | E31: =IF(ISBLANK(Ranking_Pivot!D13),"",(Ranking_Pivot!D13)&" GB") -> 2048 GB | F31: =IF(ISBLANK(Ranking_Pivot!E13),"",Ranking_Pivot!E13&" """) -> 16 " | G31: =IF(ISBLANK(Ranking_Pivot!F13),"",Ranking_Pivot!F13) -> 3840 x 2400 | H31: =IF(ISBLANK(Ranking_Pivot!G13),"",Ranking_Pivot!G13) -> 162029 | I31: =IF(ISBLANK(Ranking_Pivot!H13),"",Ranking_Pivot!H13) -> 45108 | J31: =IF(ISBLANK(Ranking_Table[[#This Row],[Lowest Price]]),"",IF(Ranking_Table[[#This Row],[Lowest Price]]=MIN(Ranking_Table[Lowest Price]), "Most Affordable", IF(Ranking_Table[[#This Row],[Lowest Price]]=MAX(Ranking_Table[Lowest Price]), "Most Expensive", "")))
B32: =IF(ISBLANK(Ranking_Pivot!A14),"",Ranking_Pivot!A14) -> Asus TUF Gaming A14 | C32: =IF(ISBLANK(Ranking_Pivot!B14),"",Ranking_Pivot!B14) -> 3 | D32: =IF(ISBLANK(Ranking_Pivot!C14),"",(Ranking_Pivot!C14)&" GB") -> 32 GB | E32: =IF(ISBLANK(Ranking_Pivot!D14),"",(Ranking_Pivot!D14)&" GB") -> 2048 GB | F32: =IF(ISBLANK(Ranking_Pivot!E14),"",Ranking_Pivot!E14&" """) -> 14 " | G32: =IF(ISBLANK(Ranking_Pivot!F14),"",Ranking_Pivot!F14) -> 2560 x 1600 | H32: =IF(ISBLANK(Ranking_Pivot!G14),"",Ranking_Pivot!G14) -> 84252 | I32: =IF(ISBLANK(Ranking_Pivot!H14),"",Ranking_Pivot!H14) -> 45717 | J32: =IF(ISBLANK(Ranking_Table[[#This Row],[Lowest Price]]),"",IF(Ranking_Table[[#This Row],[Lowest Price]]=MIN(Ranking_Table[Lowest Price]), "Most Affordable", IF(Ranking_Table[[#This Row],[Lowest Price]]=MAX(Ranking_Table[Lowest Price]), "Most Expensive", "")))
B33: =IF(ISBLANK(Ranking_Pivot!A15),"",Ranking_Pivot!A15) -> Apple MacBook Air M3 | C33: =IF(ISBLANK(Ranking_Pivot!B15),"",Ranking_Pivot!B15) -> 28 | D33: =IF(ISBLANK(Ranking_Pivot!C15),"",(Ranking_Pivot!C15)&" GB") -> 24 GB | E33: =IF(ISBLANK(Ranking_Pivot!D15),"",(Ranking_Pivot!D15)&" GB") -> 512 GB | F33: =IF(ISBLANK(Ranking_Pivot!E15),"",Ranking_Pivot!E15&" """) -> 15.3 " | G33: =IF(ISBLANK(Ranking_Pivot!F15),"",Ranking_Pivot!F15) -> 2880 x 1864 | H33: =IF(ISBLANK(Ranking_Pivot!G15),"",Ranking_Pivot!G15) -> 61963 | I33: =IF(ISBLANK(Ranking_Pivot!H15),"",Ranking_Pivot!H15) -> 45658 | J33: =IF(ISBLANK(Ranking_Table[[#This Row],[Lowest Price]]),"",IF(Ranking_Table[[#This Row],[Lowest Price]]=MIN(Ranking_Table[Lowest Price]), "Most Affordable", IF(Ranking_Table[[#This Row],[Lowest Price]]=MAX(Ranking_Table[Lowest Price]), "Most Expensive", "")))
... B36: =IF(ISBLANK(Ranking_Pivot!A18),"",Ranking_Pivot!A18) -> Asus ROG Strix G16 | C36: =IF(ISBLANK(Ranking_Pivot!B18),"",Ranking_Pivot!B18) -> 7 | D36: =IF(ISBLANK(Ranking_Pivot!C18),"",(Ranking_Pivot!C18)&" GB") -> 32 GB | E36: =IF(ISBLANK(Ranking_Pivot!D18),"",(Ranking_Pivot!D18)&" GB") -> 1024 GB | F36: =IF(ISBLANK(Ranking_Pivot!E18),"",Ranking_Pivot!E18&" """) -> 16 " | G36: =IF(ISBLANK(Ranking_Pivot!F18),"",Ranking_Pivot!F18) -> 2560 x 1600 | H36: =IF(ISBLANK(Ranking_Pivot!G18),"",Ranking_Pivot!G18) -> 70583 | I36: =IF(ISBLANK(Ranking_Pivot!H18),"",Ranking_Pivot!H18) -> 45778 | J36: =IF(ISBLANK(Ranking_Table[[#This Row],[Lowest Price]]),"",IF(Ranking_Table[[#This Row],[Lowest Price]]=MIN(Ranking_Table[Lowest Price]), "Most Affordable", IF(Ranking_Table[[#This Row],[Lowest Price]]=MAX(Ranking_Table[Lowest Price]), "Most Expensive", "")))

Sheet user_profiles
A1: user | B1: performance | C1: display | D1: price | E1: recency | F1: popularity
A2: student | B2: 0.15 | C2: 0.15 | D2: 0.6 | E2: 0.05 | F2: 0.05
A3: office | B3: 0.25 | C3: 0.25 | D3: 0.25 | E3: 0.15 | F3: 0.1
A4: gamer | B4: 0.5 | C4: 0.25 | D4: 0.1 | E4: 0.1 | F4: 0.05
A5: designer | B5: 0.35 | C5: 0.35 | D5: 0.1 | E5: 0.1 | F5: 0.1

Sheet cpu_ref
A1: brand | B1: family | C1: tier | D1: generation | E1: gen_code
A2: Intel | B2: Core | C2: i3 | D2: 10th | E2: 10000
A3: Intel | B3: Core | C3: i5 | D3: 10th | E3: 10000
A4: Intel | B4: Core | C4: i7 | D4: 10th | E4: 10000
A5: Intel | B5: Core | C5: i9 | D5: 10th | E5: 10000
A6: Intel | B6: Core | C6: i3 | D6: 1st | E6: 1000
A7: Intel | B7: Core | C7: i5 | D7: 1st | E7: 1000
A8: Intel | B8: Core | C8: i7 | D8: 1st | E8: 1000
A9: Intel | B9: Core | C9: i9 | D9: 1st | E9: 1000
A10: Intel | B10: Core | C10: i3 | D10: 2nd | E10: 2000
A11: Intel | B11: Core | C11: i5 | D11: 2nd | E11: 2000
A12: Intel | B12: Core | C12: i7 | D12: 2nd | E12: 2000
... A57: Intel | B57: Core | C57: i9 | D57: 14th | E57: 14000
A58: Intel | B58: Pentium | C58: Silver
A59: Intel | B59: Pentium | C59: Gold | E59: 7000
A60: Intel | B60: Celeron | C60: N
A61: Intel | B61: Celeron | C61: J
A62: Intel | B62: Xeon | C62: E | E62: 2000
A63: Intel | B63: Xeon | C63: W | E63: 3000
A64: Intel | B64: Xeon | C64: W | E64: 10000
A65: Intel | B65: Xeon | C65: W | E65: 1000
A66: Intel | B66: Xeon | C66: W3 | E66: 2000
A67: Intel | B67: Xeon | C67: W3 | E67: 3000
A68: Intel | B68: Xeon | C68: W5 | E68: 2000
A69: Intel | B69: Xeon | C69: W5 | E69: 3000
A70: Intel | B70: Xeon | C70: W7 | E70: 2000
A71: Intel | B71: Xeon | C71: W7 | E71: 3000
A72: Intel | B72: Xeon | C72: W9 | E72: 2000
A73: Intel | B73: Xeon | C73: W9 | E73: 3000
A74: Intel | B74: Xeon | C74: Scalable
A75: Intel | B75: Xeon | C75: Gold | E75: 6000
A76: Intel | B76: Xeon | C76: Gold | E76: 5000
A77: Intel | B77: Xeon | C77: Platinum | E77: 8000
A78: Intel | B78: Xeon | C78: Silver | E78: 4000
A79: Intel | B79: Atom | C79: N | D79: 10th
A80: Intel | B80: Atom | C80: E | D80: 10th
A81: AMD | B81: Ryzen | C81: 3 | D81: Zen 1 | E81: 1000
A82: AMD | B82: Ryzen | C82: 5 | D82: Zen 1 | E82: 1000
A83: AMD | B83: Ryzen | C83: 7 | D83: Zen 1 | E83: 1000
A84: AMD | B84: Ryzen | C84: 3 | D84: Zen+ | E84: 2000
...

Sheet perf_buckets
A1: perf_tier | B1: index_min | C1: index_max
A2: Entry | B2: 0 | C2: 0.6
A3: Mainstream | B3: 0.6 | C3: 0.9
A4: Baseline | B4: 0.9 | C4: 1.1
A5: Performance | B5: 1.1 | C5: 1.5
A6: High-End | B6: 1.5 | C6: 2
A7: Extreme | B7: 2 | C7: 99
